Workbook

Sheet 体检表
A1: 姓名 | B1: 出生日期 | C1: 性别 | D1: 身高（厘米） | E1: 体重（kg） | F1: 左眼视力 | G1: 右眼视力 | I1: 女生总人数
A2: 萧建文 | B2: =MID(体检人信息表!B2,7,4)&"年"&MID(体检人信息表!B2,11,2)&"月"&MID(体检人信息表!B2,13,2)&"日" -> 2004年01月05日 | C2: =IF(MOD(MID(体检人信息表!B2,17,1)/2,1),"男","女") -> 男 | D2: 181 | E2: 70 | F2: 5 | G2: 5.1 | I2: =COUNTIF(C:C,"女") -> 28
A3: 宋志铭 | B3: =MID(体检人信息表!B3,7,4)&"年"&MID(体检人信息表!B3,11,2)&"月"&MID(体检人信息表!B3,13,2)&"日" -> 2005年12月19日 | C3: =IF(MOD(MID(体检人信息表!B3,17,1)/2,1),"男","女") -> 男 | D3: 182 | E3: 71.3 | F3: 4.2 | G3: 4.3 | I3: 男生总人数
A4: 王家豪 | B4: =MID(体检人信息表!B4,7,4)&"年"&MID(体检人信息表!B4,11,2)&"月"&MID(体检人信息表!B4,13,2)&"日" -> 2005年03月29日 | C4: =IF(MOD(MID(体检人信息表!B4,17,1)/2,1),"男","女") -> 男 | D4: 171 | E4: 75 | F4: 5 | G4: 5 | I4: =COUNTIF(C:C,"男") -> 37
A5: 林朝瑜 | B5: =MID(体检人信息表!B5,7,4)&"年"&MID(体检人信息表!B5,11,2)&"月"&MID(体检人信息表!B5,13,2)&"日" -> 2004年04月27日 | C5: =IF(MOD(MID(体检人信息表!B5,17,1)/2,1),"男","女") -> 男 | D5: 165 | E5: 60 | F5: 4.4 | G5: 4.5
A6: 陈柏哲 | B6: =MID(体检人信息表!B6,7,4)&"年"&MID(体检人信息表!B6,11,2)&"月"&MID(体检人信息表!B6,13,2)&"日" -> 2005年05月24日 | C6: =IF(MOD(MID(体检人信息表!B6,17,1)/2,1),"男","女") -> 男 | D6: 182 | E6: 71.3 | F6: 4.7 | G6: 4.7
A7: 林柏杰 | B7: =MID(体检人信息表!B7,7,4)&"年"&MID(体检人信息表!B7,11,2)&"月"&MID(体检人信息表!B7,13,2)&"日" -> 2004年05月28日 | C7: =IF(MOD(MID(体检人信息表!B7,17,1)/2,1),"男","女") -> 男 | D7: 180 | E7: 70.6 | F7: 4.8 | G7: 4.9
A8: 林政翰 | B8: =MID(体检人信息表!B8,7,4)&"年"&MID(体检人信息表!B8,11,2)&"月"&MID(体检人信息表!B8,13,2)&"日" -> 2005年03月04日 | C8: =IF(MOD(MID(体检人信息表!B8,17,1)/2,1),"男","女") -> 女 | D8: 178 | E8: 79 | F8: 5 | G8: 5
A9: 陈宜静 | B9: =MID(体检人信息表!B9,7,4)&"年"&MID(体检人信息表!B9,11,2)&"月"&MID(体检人信息表!B9,13,2)&"日" -> 2005年03月27日 | C9: =IF(MOD(MID(体检人信息表!B9,17,1)/2,1),"男","女") -> 女 | D9: 164 | E9: 65 | F9: 5.1 | G9: 5.1
A10: 陈筱易 | B10: =MID(体检人信息表!B10,7,4)&"年"&MID(体检人信息表!B10,11,2)&"月"&MID(体检人信息表!B10,13,2)&"日" -> 2005年04月29日 | C10: =IF(MOD(MID(体检人信息表!B10,17,1)/2,1),"男","女") -> 男 | D10: 176 | E10: 78 | F10: 5 | G10: 5
A11: 李伟合 | B11: =MID(体检人信息表!B11,7,4)&"年"&MID(体检人信息表!B11,11,2)&"月"&MID(体检人信息表!B11,13,2)&"日" -> 2005年08月17日 | C11: =IF(MOD(MID(体检人信息表!B11,17,1)/2,1),"男","女") -> 女 | D11: 179 | E11: 71.6 | F11: 5.1 | G11: 5.1
A12: 郭俊安 | B12: =MID(体检人信息表!B12,7,4)&"年"&MID(体检人信息表!B12,11,2)&"月"&MID(体检人信息表!B12,13,2)&"日" -> 2005年10月26日 | C12: =IF(MOD(MID(体检人信息表!B12,17,1)/2,1),"男","女") -> 男 | D12: 183 | E12: 78 | F12: 5 | G12: 4.9
A13: 陈馥卿 | B13: =MID(体检人信息表!B13,7,4)&"年"&MID(体检人信息表!B13,11,2)&"月"&MID(体检人信息表!B13,13,2)&"日" -> 2004年03月05日 | C13: =IF(MOD(MID(体检人信息表!B13,17,1)/2,1),"男","女") -> 男 | D13: 188 | E13: 79 | F13: 5 | G13: 5.1
A14: 王雅琪 | B14: =MID(体检人信息表!B14,7,4)&"年"&MID(体检人信息表!B14,11,2)&"月"&MID(体检人信息表!B14,13,2)&"日" -> 2004年07月14日 | C14: =IF(MOD(MID(体检人信息表!B14,17,1)/2,1),"男","女") -> 女 | D14: 171 | E14: 60 | F14: 4.4 | G14: 4.5
A15: 潘芳瑜 | B15: =MID(体检人信息表!B15,7,4)&"年"&MID(体检人信息表!B15,11,2)&"月"&MID(体检人信息表!B15,13,2)&"日" -> 2005年10月05日 | C15: =IF(MOD(MID(体检人信息表!B15,17,1)/2,1),"男","女") -> 男 | D15: 174 | E15: 75 | F15: 4.7 | G15: 4.7
A16: 张博虹 | B16: =MID(体检人信息表!B16,7,4)&"年"&MID(体检人信息表!B16,11,2)&"月"&MID(体检人信息表!B16,13,2)&"日" -> 2004年10月21日 | C16: =IF(MOD(MID(体检人信息表!B16,17,1)/2,1),"男","女") -> 男 | D16: 167 | E16: 68 | F16: 4.8 | G16: 4.9
... A66: 杨世昌 | B66: =MID(体检人信息表!B66,7,4)&"年"&MID(体检人信息表!B66,11,2)&"月"&MID(体检人信息表!B66,13,2)&"日" -> 2004年12月02日 | C66: =IF(MOD(MID(体检人信息表!B66,17,1)/2,1),"男","女") -> 男 | D66: 179 | E66: 68.6 | F66: 5 | G66: 5

Sheet 体检人信息表
A1: 姓名 | B1: 身份证号码
A2: 萧建文 | B2: 420101200401051055
A3: 宋志铭 | B3: 110102200512191513
A4: 王家豪 | B4: 110102200503292713
A5: 林朝瑜 | B5: 110102200404271532
A6: 陈柏哲 | B6: 140302200505240451
A7: 林柏杰 | B7: 110102200405281913
A8: 林政翰 | B8: 110103200503040920
A9: 陈宜静 | B9: 110103200503270623
A10: 陈筱易 | B10: 110103200504290936
A11: 李伟合 | B11: 430103200508171548
A12: 郭俊安 | B12: 140104200510261737
... A66: 杨世昌 | B66: 530226200412021915

Sheet 筛选
A1: 左眼视力 | B1: 右眼视力
A2: >=5.0 | B2: >=5.0
A3: 姓名 | B3: 身高（厘米） | C3: 体重（kg） | D3: 左眼视力 | E3: 右眼视力
A4: 蔡博琇 | B4: 168 | C4: 74 | D4: 5 | E4: 5
A5: 宋志铭 | B5: 182 | C5: 71.3 | D5: 4.2 | E5: 4.3
A6: 蔡君宏 | B6: 175 | C6: 71.5 | D6: 5 | E6: 5
A7: 林朝瑜 | B7: 165 | C7: 60 | D7: 4.4 | E7: 4.5
A8: 陈柏哲 | B8: 182 | C8: 71.3 | D8: 4.7 | E8: 4.7
A9: 林柏杰 | B9: 180 | C9: 70.6 | D9: 4.8 | E9: 4.9
A10: 蔡志瑞 | B10: 174 | C10: 64 | D10: 5.1 | E10: 5.1
A11: 曹淑媛 | B11: 168 | C11: 49 | D11: 5 | E11: 5
A12: 陈馥卿 | B12: 188 | C12: 79 | D12: 5 | E12: 5.1
A13: 陈金志 | B13: 182 | C13: 70.6 | D13: 5 | E13: 5
A14: 郭俊安 | B14: 183 | C14: 78 | D14: 5 | E14: 4.9
A15: 陈俊嘉 | B15: 174 | C15: 65 | D15: 5.1 | E15: 5.1
... A68: 左安琪 | B68: 156 | C68: 48 | D68: 5 | E68: 5

Sheet 分类汇总
A1: 姓名 | B1: 出生日期 | C1: 性别 | D1: 身高（厘米） | E1: 体重（kg） | F1: 左眼视力 | G1: 右眼视力
A2: 章庭尹 | B2: =MID(体检人信息表!B56,7,4)&"年"&MID(体检人信息表!B56,11,2)&"月"&MID(体检人信息表!B56,13,2)&"日" -> 2004年05月31日 | C2: =IF(MOD(MID(体检人信息表!B56,17,1)/2,1),"男","女") -> 女 | D2: 158 | E2: 45.6 | F2: 5 | G2: 5
A3: 张兆洋 | B3: =MID(体检人信息表!B31,7,4)&"年"&MID(体检人信息表!B31,11,2)&"月"&MID(体检人信息表!B31,13,2)&"日" -> 2006年10月04日 | C3: =IF(MOD(MID(体检人信息表!B31,17,1)/2,1),"男","女") -> 女 | D3: 181 | E3: 71.3 | F3: 4.8 | G3: 4.9
A4: 杨心玲 | B4: =MID(体检人信息表!B36,7,4)&"年"&MID(体检人信息表!B36,11,2)&"月"&MID(体检人信息表!B36,13,2)&"日" -> 2004年06月23日 | C4: =IF(MOD(MID(体检人信息表!B36,17,1)/2,1),"男","女") -> 女 | D4: 162 | E4: 45 | F4: 5.1 | G4: 5.1
A5: 颜怡璇 | B5: =MID(体检人信息表!B55,7,4)&"年"&MID(体检人信息表!B55,11,2)&"月"&MID(体检人信息表!B55,13,2)&"日" -> 2005年09月07日 | C5: =IF(MOD(MID(体检人信息表!B55,17,1)/2,1),"男","女") -> 女 | D5: 156 | E5: 48.6 | F5: 4.8 | G5: 4.9
A6: 萧财容 | B6: =MID(体检人信息表!B18,7,4)&"年"&MID(体检人信息表!B18,11,2)&"月"&MID(体检人信息表!B18,13,2)&"日" -> 2004年06月03日 | C6: =IF(MOD(MID(体检人信息表!B18,17,1)/2,1),"男","女") -> 女 | D6: 187 | E6: 74 | F6: 5.1 | G6: 5.1
A7: 吴佳宏 | B7: =MID(体检人信息表!B42,7,4)&"年"&MID(体检人信息表!B42,11,2)&"月"&MID(体检人信息表!B42,13,2)&"日" -> 2005年04月11日 | C7: =IF(MOD(MID(体检人信息表!B42,17,1)/2,1),"男","女") -> 女 | D7: 180 | E7: 74 | F7: 5.1 | G7: 5.1
A8: 王雅琪 | B8: =MID(体检人信息表!B14,7,4)&"年"&MID(体检人信息表!B14,11,2)&"月"&MID(体检人信息表!B14,13,2)&"日" -> 2004年07月14日 | C8: =IF(MOD(MID(体检人信息表!B14,17,1)/2,1),"男","女") -> 女 | D8: 171 | E8: 60 | F8: 4.4 | G8: 4.5
A9: 王初瑄 | B9: =MID(体检人信息表!B26,7,4)&"年"&MID(体检人信息表!B26,11,2)&"月"&MID(体检人信息表!B26,13,2)&"日" -> 2004年08月01日 | C9: =IF(MOD(MID(体检人信息表!B26,17,1)/2,1),"男","女") -> 女 | D9: 161 | E9: 50 | F9: 5.1 | G9: 5.1
A10: 谈舒涵 | B10: =MID(体检人信息表!B41,7,4)&"年"&MID(体检人信息表!B41,11,2)&"月"&MID(体检人信息表!B41,13,2)&"日" -> 2005年01月28日 | C10: =IF(MOD(MID(体检人信息表!B41,17,1)/2,1),"男","女") -> 女 | D10: 166 | E10: 54 | F10: 5 | G10: 5
A11: 林政翰 | B11: =MID(体检人信息表!B8,7,4)&"年"&MID(体检人信息表!B8,11,2)&"月"&MID(体检人信息表!B8,13,2)&"日" -> 2005年03月04日 | C11: =IF(MOD(MID(体检人信息表!B8,17,1)/2,1),"男","女") -> 女 | D11: 178 | E11: 79 | F11: 5 | G11: 5
A12: 林信宏 | B12: =MID(体检人信息表!B53,7,4)&"年"&MID(体检人信息表!B53,11,2)&"月"&MID(体检人信息表!B53,13,2)&"日" -> 2005年05月21日 | C12: =IF(MOD(MID(体检人信息表!B53,17,1)/2,1),"男","女") -> 女 | D12: 187 | E12: 60 | F12: 4.4 | G12: 4.5
A13: 林丽芬 | B13: =MID(体检人信息表!B64,7,4)&"年"&MID(体检人信息表!B64,11,2)&"月"&MID(体检人信息表!B64,13,2)&"日" -> 2006年05月11日 | C13: =IF(MOD(MID(体检人信息表!B64,17,1)/2,1),"男","女") -> 女 | D13: 165 | E13: 56 | F13: 5.1 | G13: 5.1
A14: 林慧韦 | B14: =MID(体检人信息表!B60,7,4)&"年"&MID(体检人信息表!B60,11,2)&"月"&MID(体检人信息表!B60,13,2)&"日" -> 2004年11月14日 | C14: =IF(MOD(MID(体检人信息表!B60,17,1)/2,1),"男","女") -> 女 | D14: 159 | E14: 56 | F14: 5 | G14: 4.9
A15: 李依勇 | B15: =MID(体检人信息表!B33,7,4)&"年"&MID(体检人信息表!B33,11,2)&"月"&MID(体检人信息表!B33,13,2)&"日" -> 2005年09月29日 | C15: =IF(MOD(MID(体检人信息表!B33,17,1)/2,1),"男","女") -> 女 | D15: 181 | E15: 72.6 | F15: 4.4 | G15: 4.5
A16: 李伟合 | B16: =MID(体检人信息表!B11,7,4)&"年"&MID(体检人信息表!B11,11,2)&"月"&MID(体检人信息表!B11,13,2)&"日" -> 2005年08月17日 | C16: =IF(MOD(MID(体检人信息表!B11,17,1)/2,1),"男","女") -> 女 | D16: 179 | E16: 71.6 | F16: 5.1 | G16: 5.1
A17: 江天勋 | B17: =MID(体检人信息表!B38,7,4)&"年"&MID(体检人信息表!B38,11,2)&"月"&MID(体检人信息表!B38,13,2)&"日" -> 2005年01月11日 | C17: =IF(MOD(MID(体检人信息表!B38,17,1)/2,1),"男","女") -> 女 | D17: 174 | E17: 51.3 | F17: 5 | G17: 5.1
A18: 黄启善 | B18: =MID(体检人信息表!B57,7,4)&"年"&MID(体检人信息表!B57,11,2)&"月"&MID(体检人信息表!B57,13,2)&"日" -> 2004年06月24日 | C18: =IF(MOD(MID(体检人信息表!B57,17,1)/2,1),"男","女") -> 女 | D18: 176 | E18: 71.3 | F18: 5.1 | G18: 5.1
A19: 黄美善 | B19: =MID(体检人信息表!B47,7,4)&"年"&MID(体检人信息表!B47,11,2)&"月"&MID(体检人信息表!B47,13,2)&"日" -> 2006年12月06日 | C19: =IF(MOD(MID(体检人信息表!B47,17,1)/2,1),"男","女") -> 女 | D19: 156 | E19: 48 | F19: 5 | G19: 5
A20: 黄惠茹 | B20: =MID(体检人信息表!B54,7,4)&"年"&MID(体检人信息表!B54,11,2)&"月"&MID(体检人信息表!B54,13,2)&"日" -> 2004年09月16日 | C20: =IF(MOD(MID(体检人信息表!B54,17,1)/2,1),"男","女") -> 女 | D20: 165 | E20: 45.9 | F20: 4.7 | G20: 4.7
A21: 高名民 | B21: =MID(体检人信息表!B29,7,4)&"年"&MID(体检人信息表!B29,11,2)&"月"&MID(体检人信息表!B29,13,2)&"日" -> 2006年08月07日 | C21: =IF(MOD(MID(体检人信息表!B29,17,1)/2,1),"男","女") -> 女 | D21: 170 | E21: 61 | F21: 4.4 | G21: 4.5
A22: 邓嘉玲 | B22: =MID(体检人信息表!B49,7,4)&"年"&MID(体检人信息表!B49,11,2)&"月"&MID(体检人信息表!B49,13,2)&"日" -> 2005年11月14日 | C22: =IF(MOD(MID(体检人信息表!B49,17,1)/2,1),"男","女") -> 女 | D22: 153 | E22: 49 | F22: 5 | G22: 5
A23: 陈宜静 | B23: =MID(体检人信息表!B9,7,4)&"年"&MID(体检人信息表!B9,11,2)&"月"&MID(体检人信息表!B9,13,2)&"日" -> 2005年03月27日 | C23: =IF(MOD(MID(体检人信息表!B9,17,1)/2,1),"男","女") -> 女 | D23: 164 | E23: 65 | F23: 5.1 | G23: 5.1
A24: 陈彦亨 | B24: =MID(体检人信息表!B63,7,4)&"年"&MID(体检人信息表!B63,11,2)&"月"&MID(体检人信息表!B63,13,2)&"日" -> 2006年11月26日 | C24: =IF(MOD(MID(体检人信息表!B63,17,1)/2,1),"男","女") -> 女 | D24: 184 | E24: 69.6 | F24: 5 | G24: 5
A25: 陈佩芬 | B25: =MID(体检人信息表!B39,7,4)&"年"&MID(体检人信息表!B39,11,2)&"月"&MID(体检人信息表!B39,13,2)&"日" -> 2005年10月23日 | C25: =IF(MOD(MID(体检人信息表!B39,17,1)/2,1),"男","女") -> 女 | D25: 158 | E25: 52.6 | F25: 5 | G25: 5
A26: 陈金志 | B26: =MID(体检人信息表!B32,7,4)&"年"&MID(体检人信息表!B32,11,2)&"月"&MID(体检人信息表!B32,13,2)&"日" -> 2006年06月16日 | C26: =IF(MOD(MID(体检人信息表!B32,17,1)/2,1),"男","女") -> 女 | D26: 182 | E26: 70.6 | F26: 5 | G26: 5
A27: 陈法璇 | B27: =MID(体检人信息表!B65,7,4)&"年"&MID(体检人信息表!B65,11,2)&"月"&MID(体检人信息表!B65,13,2)&"日" -> 2005年09月16日 | C27: =IF(MOD(MID(体检人信息表!B65,17,1)/2,1),"男","女") -> 女 | D27: 145 | E27: 45 | F27: 4.2 | G27: 4.3
A28: 曹淑媛 | B28: =MID(体检人信息表!B52,7,4)&"年"&MID(体检人信息表!B52,11,2)&"月"&MID(体检人信息表!B52,13,2)&"日" -> 2005年11月26日 | C28: =IF(MOD(MID(体检人信息表!B52,17,1)/2,1),"男","女") -> 女 | D28: 168 | E28: 49 | F28: 5 | G28: 5
A29: 蔡君宏 | B29: =MID(体检人信息表!B58,7,4)&"年"&MID(体检人信息表!B58,11,2)&"月"&MID(体检人信息表!B58,13,2)&"日" -> 2005年12月06日 | C29: =IF(MOD(MID(体检人信息表!B58,17,1)/2,1),"男","女") -> 女 | D29: 175 | E29: 71.5 | F29: 5 | G29: 5
C30: 女 平均值 | D30: =SUBTOTAL(1,D2:D29) -> 169.32143 | E30: =SUBTOTAL(1,E2:E29) -> 59.553571
A31: 左安琪 | B31: =MID(体检人信息表!B23,7,4)&"年"&MID(体检人信息表!B23,11,2)&"月"&MID(体检人信息表!B23,13,2)&"日" -> 2005年04月23日 | C31: =IF(MOD(MID(体检人信息表!B23,17,1)/2,1),"男","女") -> 男 | D31: 156 | E31: 48 | F31: 5 | G31: 5
A32: 周禹诚 | B32: =MID(体检人信息表!B43,7,4)&"年"&MID(体检人信息表!B43,11,2)&"月"&MID(体检人信息表!B43,13,2)&"日" -> 2005年08月09日 | C32: =IF(MOD(MID(体检人信息表!B43,17,1)/2,1),"男","女") -> 男 | D32: 178 | E32: 69 | F32: 4.9 | G32: 4.9
A33: 张淑峰 | B33: =MID(体检人信息表!B25,7,4)&"年"&MID(体检人信息表!B25,11,2)&"月"&MID(体检人信息表!B25,13,2)&"日" -> 2005年12月28日 | C33: =IF(MOD(MID(体检人信息表!B25,17,1)/2,1),"男","女") -> 男 | D33: 174 | E33: 59 | F33: 5 | G33: 5
A34: 张博虹 | B34: =MID(体检人信息表!B16,7,4)&"年"&MID(体检人信息表!B16,11,2)&"月"&MID(体检人信息表!B16,13,2)&"日" -> 2004年10月21日 | C34: =IF(MOD(MID(体检人信息表!B16,17,1)/2,1),"男","女") -> 男 | D34: 167 | E34: 68 | F34: 4.8 | G34: 4.9
A35: 余家玮 | B35: =MID(体检人信息表!B45,7,4)&"年"&MID(体检人信息表!B45,11,2)&"月"&MID(体检人信息表!B45,13,2)&"日" -> 2004年12月22日 | C35: =IF(MOD(MID(体检人信息表!B45,17,1)/2,1),"男","女") -> 男 | D35: 180 | E35: 66.8 | F35: 4.7 | G35: 4.7
A36: 杨世昌 | B36: =MID(体检人信息表!B66,7,4)&"年"&MID(体检人信息表!B66,11,2)&"月"&MID(体检人信息表!B66,13,2)&"日" -> 2004年12月02日 | C36: =IF(MOD(MID(体检人信息表!B66,17,1)/2,1),"男","女") -> 男 | D36: 179 | E36: 68.6 | F36: 5 | G36: 5
A37: 杨丹菱 | B37: =MID(体检人信息表!B37,7,4)&"年"&MID(体检人信息表!B37,11,2)&"月"&MID(体检人信息表!B37,13,2)&"日" -> 2005年10月13日 | C37: =IF(MOD(MID(体检人信息表!B37,17,1)/2,1),"男","女") -> 男 | D37: 166 | E37: 48 | F37: 5 | G37: 4.9
A38: 许育萱 | B38: =MID(体检人信息表!B62,7,4)&"年"&MID(体检人信息表!B62,11,2)&"月"&MID(体检人信息表!B62,13,2)&"日" -> 2004年09月06日 | C38: =IF(MOD(MID(体检人信息表!B62,17,1)/2,1),"男","女") -> 男 | D38: 165 | E38: 59 | F38: 4.4 | G38: 4.5
A39: 萧建文 | B39: =MID(体检人信息表!B2,7,4)&"年"&MID(体检人信息表!B2,11,2)&"月"&MID(体检人信息表!B2,13,2)&"日" -> 2004年01月05日 | C39: =IF(MOD(MID(体检人信息表!B2,17,1)/2,1),"男","女") -> 男 | D39: 181 | E39: 70 | F39: 5 | G39: 5.1
A40: 吴睿芝 | B40: =MID(体检人信息表!B20,7,4)&"年"&MID(体检人信息表!B20,11,2)&"月"&MID(体检人信息表!B20,13,2)&"日" -> 2004年05月13日 | C40: =IF(MOD(MID(体检人信息表!B20,17,1)/2,1),"男","女") -> 男 | D40: 181 | E40: 76 | F40: 5.1 | G40: 5.1
...
