Workbook

Sheet 2016年消费
A1: 顾客编号 | B1: 季度 | C1: 消费金额
A2: C00001 | B2: 第一季度 | C2: 4578
A3: =A2 -> C00001 | B3: 第二季度 | C3: 5035
A4: =A3 -> C00001 | B4: 第三季度 | C4: 5035
A5: =A4 -> C00001 | B5: 第四季度 | C5: 2060
A6: C00002 | B6: 第一季度 | C6: 8240
A7: =A6 -> C00002 | B7: 第二季度 | C7: 4120
A8: =A7 -> C00002 | B8: 第三季度 | C8: 2518
A9: =A8 -> C00002 | B9: 第四季度 | C9: 4120
A10: C00003 | B10: 第一季度 | C10: 8240
A11: =A10 -> C00003 | B11: 第二季度 | C11: 12588
A12: =A11 -> C00003 | B12: 第三季度 | C12: 6866
A13: =A12 -> C00003 | B13: 第四季度 | C13: 4120
A14: C00004 | B14: 第一季度 | C14: 20141
A15: =A14 -> C00004 | B15: 第二季度 | C15: 7553
A16: =A15 -> C00004 | B16: 第三季度 | C16: 12588
A17: C00005 | B17: 第一季度 | C17: 4578
A18: =A17 -> C00005 | B18: 第二季度 | C18: 4578
A19: =A18 -> C00005 | B19: 第三季度 | C19: 9155
A20: =A19 -> C00005 | B20: 第四季度 | C20: 2289
A21: C00006 | B21: 第一季度 | C21: 2060
A22: =A21 -> C00006 | B22: 第二季度 | C22: 7553
A23: =A22 -> C00006 | B23: 第三季度 | C23: 5035
A24: C00007 | B24: 第一季度 | C24: 4120
A25: =A24 -> C00007 | B25: 第二季度 | C25: 2060
A26: =A25 -> C00007 | B26: 第三季度 | C26: 4120
A27: =A26 -> C00007 | B27: 第四季度 | C27: 4120
A28: C00008 | B28: 第一季度 | C28: 12360
A29: =A28 -> C00008 | B29: 第三季度 | C29: 4120
A30: =A29 -> C00008 | B30: 第四季度 | C30: 2518
A31: C00009 | B31: 第一季度 | C31: 12588
A32: =A31 -> C00009 | B32: 第二季度 | C32: 4120
A33: =A32 -> C00009 | B33: 第三季度 | C33: 9155
A34: =A33 -> C00009 | B34: 第四季度 | C34: 12360
A35: C00010 | B35: 第一季度 | C35: 12360
A36: =A35 -> C00010 | B36: 第二季度 | C36: 6866
A37: =A36 -> C00010 | B37: 第三季度 | C37: 6180
A38: =A37 -> C00010 | B38: 第四季度 | C38: 16022
A39: C00011 | B39: 第一季度 | C39: 5035
A40: =A39 -> C00011 | B40: 第二季度 | C40: 5035
...

Sheet 各年龄段人数

Sheet 客户资料
A1: 顾客编号 | B1: 性别 | C1: 生日 | D1: 年龄 | E1: 年龄段 | F1: 年消费金额
A2: C00001 | B2: 男 | C2: 25158 | D2: =DATEDIF(C2,"2017-1-1","y") -> 48 | E2: =VLOOKUP(D2,按年龄和性别!$A$16:$B$27,2,TRUE) -> 45-49岁 | F2: =SUMIFS('2016年消费'!$C$1:$C$364,'2016年消费'!$A$1:$A$364,A2) -> 16708
A3: C00002 | B3: 女 | C3: 26844 | D3: =DATEDIF(C3,"2017-1-1","y") -> 43 | E3: =VLOOKUP(D3,按年龄和性别!$A$16:$B$27,2,TRUE) -> 40-44岁 | F3: =SUMIFS('2016年消费'!$C$1:$C$364,'2016年消费'!$A$1:$A$364,A3) -> 18998
A4: C00003 | B4: 女 | C4: 26821 | D4: =DATEDIF(C4,"2017-1-1","y") -> 43 | E4: =VLOOKUP(D4,按年龄和性别!$A$16:$B$27,2,TRUE) -> 40-44岁 | F4: =SUMIFS('2016年消费'!$C$1:$C$364,'2016年消费'!$A$1:$A$364,A4) -> 31814
A5: C00004 | B5: 男 | C5: 26210 | D5: =DATEDIF(C5,"2017-1-1","y") -> 45 | E5: =VLOOKUP(D5,按年龄和性别!$A$16:$B$27,2,TRUE) -> 45-49岁 | F5: =SUMIFS('2016年消费'!$C$1:$C$364,'2016年消费'!$A$1:$A$364,A5) -> 40282
A6: C00005 | B6: 女 | C6: 22633 | D6: =DATEDIF(C6,"2017-1-1","y") -> 55 | E6: =VLOOKUP(D6,按年龄和性别!$A$16:$B$27,2,TRUE) -> 55-59岁 | F6: =SUMIFS('2016年消费'!$C$1:$C$364,'2016年消费'!$A$1:$A$364,A6) -> 20600
A7: C00006 | B7: 男 | C7: 23609 | D7: =DATEDIF(C7,"2017-1-1","y") -> 52 | E7: =VLOOKUP(D7,按年龄和性别!$A$16:$B$27,2,TRUE) -> 50-54岁 | F7: =SUMIFS('2016年消费'!$C$1:$C$364,'2016年消费'!$A$1:$A$364,A7) -> 14648
A8: C00007 | B8: 女 | C8: 31834 | D8: =DATEDIF(C8,"2017-1-1","y") -> 29 | E8: =VLOOKUP(D8,按年龄和性别!$A$16:$B$27,2,TRUE) -> 30岁以下 | F8: =SUMIFS('2016年消费'!$C$1:$C$364,'2016年消费'!$A$1:$A$364,A8) -> 14420
A9: C00008 | B9: 男 | C9: 32078 | D9: =DATEDIF(C9,"2017-1-1","y") -> 29 | E9: =VLOOKUP(D9,按年龄和性别!$A$16:$B$27,2,TRUE) -> 30岁以下 | F9: =SUMIFS('2016年消费'!$C$1:$C$364,'2016年消费'!$A$1:$A$364,A9) -> 18998
A10: C00009 | B10: 男 | C10: 23355 | D10: =DATEDIF(C10,"2017-1-1","y") -> 53 | E10: =VLOOKUP(D10,按年龄和性别!$A$16:$B$27,2,TRUE) -> 50-54岁 | F10: =SUMIFS('2016年消费'!$C$1:$C$364,'2016年消费'!$A$1:$A$364,A10) -> 38223
A11: C00010 | B11: 男 | C11: 26018 | D11: =DATEDIF(C11,"2017-1-1","y") -> 45 | E11: =VLOOKUP(D11,按年龄和性别!$A$16:$B$27,2,TRUE) -> 45-49岁 | F11: =SUMIFS('2016年消费'!$C$1:$C$364,'2016年消费'!$A$1:$A$364,A11) -> 41428
A12: C00011 | B12: 女 | C12: 26141 | D12: =DATEDIF(C12,"2017-1-1","y") -> 45 | E12: =VLOOKUP(D12,按年龄和性别!$A$16:$B$27,2,TRUE) -> 45-49岁 | F12: =SUMIFS('2016年消费'!$C$1:$C$364,'2016年消费'!$A$1:$A$364,A12) -> 17623
A13: C00012 | B13: 男 | C13: 16770 | D13: =DATEDIF(C13,"2017-1-1","y") -> 71 | E13: =VLOOKUP(D13,按年龄和性别!$A$16:$B$27,2,TRUE) -> 70-74岁 | F13: =SUMIFS('2016年消费'!$C$1:$C$364,'2016年消费'!$A$1:$A$364,A13) -> 91781
... A101: C00100 | B101: 女 | C101: 24611 | D101: =DATEDIF(C101,"2017-1-1","y") -> 49 | E101: =VLOOKUP(D101,按年龄和性别!$A$16:$B$27,2,TRUE) -> 45-49岁 | F101: =SUMIFS('2016年消费'!$C$1:$C$364,'2016年消费'!$A$1:$A$364,A101) -> 140060

Sheet 按年龄和性别
A1: 年龄段 | B1: 男顾客人数 | C1: 女顾客人数 | D1: 顾客总人数
A2: 30岁以下 | B2: =COUNTIFS(客户资料!$B$1:$B$101,"男",客户资料!$E$1:$E$101,A2) -> 2 | C2: =COUNTIFS(客户资料!$B$1:$B$101,"女",客户资料!$E$1:$E$101,A2) -> 1 | D2: =SUM(B2:C2) -> 3
A3: 30-34岁 | B3: =COUNTIFS(客户资料!$B$1:$B$101,"男",客户资料!$E$1:$E$101,A3) -> 1 | C3: =COUNTIFS(客户资料!$B$1:$B$101,"女",客户资料!$E$1:$E$101,A3) -> 4 | D3: =SUM(B3:C3) -> 5
A4: 35-39岁 | B4: =COUNTIFS(客户资料!$B$1:$B$101,"男",客户资料!$E$1:$E$101,A4) -> 1 | C4: =COUNTIFS(客户资料!$B$1:$B$101,"女",客户资料!$E$1:$E$101,A4) -> 0 | D4: =SUM(B4:C4) -> 1
A5: 40-44岁 | B5: =COUNTIFS(客户资料!$B$1:$B$101,"男",客户资料!$E$1:$E$101,A5) -> 8 | C5: =COUNTIFS(客户资料!$B$1:$B$101,"女",客户资料!$E$1:$E$101,A5) -> 9 | D5: =SUM(B5:C5) -> 17
A6: 45-49岁 | B6: =COUNTIFS(客户资料!$B$1:$B$101,"男",客户资料!$E$1:$E$101,A6) -> 14 | C6: =COUNTIFS(客户资料!$B$1:$B$101,"女",客户资料!$E$1:$E$101,A6) -> 10 | D6: =SUM(B6:C6) -> 24
A7: 50-54岁 | B7: =COUNTIFS(客户资料!$B$1:$B$101,"男",客户资料!$E$1:$E$101,A7) -> 15 | C7: =COUNTIFS(客户资料!$B$1:$B$101,"女",客户资料!$E$1:$E$101,A7) -> 2 | D7: =SUM(B7:C7) -> 17
A8: 55-59岁 | B8: =COUNTIFS(客户资料!$B$1:$B$101,"男",客户资料!$E$1:$E$101,A8) -> 11 | C8: =COUNTIFS(客户资料!$B$1:$B$101,"女",客户资料!$E$1:$E$101,A8) -> 6 | D8: =SUM(B8:C8) -> 17
A9: 60-64岁 | B9: =COUNTIFS(客户资料!$B$1:$B$101,"男",客户资料!$E$1:$E$101,A9) -> 4 | C9: =COUNTIFS(客户资料!$B$1:$B$101,"女",客户资料!$E$1:$E$101,A9) -> 1 | D9: =SUM(B9:C9) -> 5
A10: 65-69岁 | B10: =COUNTIFS(客户资料!$B$1:$B$101,"男",客户资料!$E$1:$E$101,A10) -> 4 | C10: =COUNTIFS(客户资料!$B$1:$B$101,"女",客户资料!$E$1:$E$101,A10) -> 1 | D10: =SUM(B10:C10) -> 5
A11: 70-74岁 | B11: =COUNTIFS(客户资料!$B$1:$B$101,"男",客户资料!$E$1:$E$101,A11) -> 3 | C11: =COUNTIFS(客户资料!$B$1:$B$101,"女",客户资料!$E$1:$E$101,A11) -> 2 | D11: =SUM(B11:C11) -> 5
A12: 75岁以上 | B12: =COUNTIFS(客户资料!$B$1:$B$101,"男",客户资料!$E$1:$E$101,A12) -> 0 | C12: =COUNTIFS(客户资料!$B$1:$B$101,"女",客户资料!$E$1:$E$101,A12) -> 1 | D12: =SUM(B12:C12) -> 1
A13: 合计 | B13: =SUM(B2:B12) -> 63 | C13: =SUM(C2:C12) -> 37 | D13: =SUM(D2:D12) -> 100
A16: 年龄 | B16: 年龄段
A17: 0 | B17: 30岁以下
A18: 30 | B18: 30-34岁
A19: 35 | B19: 35-39岁
A20: 40 | B20: 40-44岁
A21: 45 | B21: 45-49岁
A22: 50 | B22: 50-54岁
A23: 55 | B23: 55-59岁
A24: 60 | B24: 60-64岁
A25: 65 | B25: 65-69岁
A26: 70 | B26: 70-74岁
A27: 75 | B27: 75岁以上
