Workbook

Sheet 期末成绩表
A1: 初三（5）班第一学期期末成绩表
A2: 学号 | B2: 姓名 | C2: 语文 | D2: 数学 | E2: 英语 | F2: 物理 | G2: 化学 | H2: 品德 | I2: 历史 | J2: 总分 | K2: 总分排名
A3: C121401 | B3: =VLOOKUP(A3,学生信息表!$A$1:$B$56,2,FALSE) -> 陈金志 | C3: 97 | D3: 85 | E3: 82 | F3: 89 | G3: 69 | H3: 97 | I3: 83 | J3: =SUM(C3:I3) -> 602 | K3: ="第"&RANK(J3,J3:J46)&"名" -> 第30名
A4: C121402 | B4: =VLOOKUP(A4,学生信息表!$A$1:$B$56,2,FALSE) -> 蔡君宏 | C4: 99 | D4: 116 | E4: 89 | F4: 100 | G4: 83 | H4: 95 | I4: 100 | J4: =SUM(C4:I4) -> 682 | K4: ="第"&RANK(J4,J3:J46)&"名" -> 第1名
A5: C121403 | B5: =VLOOKUP(A5,学生信息表!$A$1:$B$56,2,FALSE) -> 吴佳宏 | C5: 98 | D5: 113 | E5: 92 | F5: 98 | G5: 69 | H5: 92 | I5: 84 | J5: =SUM(C5:I5) -> 646 | K5: ="第"&RANK(J5,J3:J46)&"名" -> 第8名
A6: C121404 | B6: =VLOOKUP(A6,学生信息表!$A$1:$B$56,2,FALSE) -> 李政彬 | C6: 87 | D6: 99 | E6: 97 | F6: 93 | G6: 68 | H6: 87 | I6: 74 | J6: =SUM(C6:I6) -> 605 | K6: ="第"&RANK(J6,J3:J46)&"名" -> 第29名
A7: C121405 | B7: =VLOOKUP(A7,学生信息表!$A$1:$B$56,2,FALSE) -> 黄惠茹 | C7: 103 | D7: 100 | E7: 85 | F7: 95 | G7: 82 | H7: 77 | I7: 92 | J7: =SUM(C7:I7) -> 634 | K7: ="第"&RANK(J7,J3:J46)&"名" -> 第15名
A8: C121406 | B8: =VLOOKUP(A8,学生信息表!$A$1:$B$56,2,FALSE) -> 林雅婷 | C8: 96 | D8: 113 | E8: 96 | F8: 80 | G8: 91 | H8: 91 | I8: 95 | J8: =SUM(C8:I8) -> 662 | K8: ="第"&RANK(J8,J3:J46)&"名" -> 第3名
A9: C121407 | B9: =VLOOKUP(A9,学生信息表!$A$1:$B$56,2,FALSE) -> 邓嘉玲 | C9: 109 | D9: 79 | E9: 93 | F9: 97 | G9: 97 | H9: 88 | I9: 89 | J9: =SUM(C9:I9) -> 652 | K9: ="第"&RANK(J9,J3:J46)&"名" -> 第5名
A10: C121408 | B10: =VLOOKUP(A10,学生信息表!$A$1:$B$56,2,FALSE) -> 林丽芬 | C10: 81 | D10: 96 | E10: 96 | F10: 74 | G10: 80 | H10: 75 | I10: 94 | J10: =SUM(C10:I10) -> 596 | K10: ="第"&RANK(J10,J3:J46)&"名" -> 第32名
A11: C121409 | B11: =VLOOKUP(A11,学生信息表!$A$1:$B$56,2,FALSE) -> 林敏茂 | C11: 103 | D11: 75 | E11: 92 | F11: 92 | G11: 74 | H11: 80 | I11: 67 | J11: =SUM(C11:I11) -> 583 | K11: ="第"&RANK(J11,J3:J46)&"名" -> 第38名
A12: C121410 | B12: =VLOOKUP(A12,学生信息表!$A$1:$B$56,2,FALSE) -> 黄美善 | C12: 95 | D12: 83 | E12: 78 | F12: 80 | G12: 73 | H12: 71 | I12: 64 | J12: =SUM(C12:I12) -> 544 | K12: ="第"&RANK(J12,J3:J46)&"名" -> 第44名
A13: C121411 | B13: =VLOOKUP(A13,学生信息表!$A$1:$B$56,2,FALSE) -> 杜思颖 | C13: 90 | D13: 107 | E13: 91 | F13: 90 | G13: 72 | H13: 88 | I13: 96 | J13: =SUM(C13:I13) -> 634 | K13: ="第"&RANK(J13,J3:J46)&"名" -> 第15名
A14: C121412 | B14: =VLOOKUP(A14,学生信息表!$A$1:$B$56,2,FALSE) -> 陈俊嘉 | C14: 83 | D14: 74 | E14: 96 | F14: 74 | G14: 68 | H14: 77 | I14: 77 | J14: =SUM(C14:I14) -> 549 | K14: ="第"&RANK(J14,J3:J46)&"名" -> 第42名
A15: C121413 | B15: =VLOOKUP(A15,学生信息表!$A$1:$B$56,2,FALSE) -> 江天勋 | C15: 100 | D15: 90 | E15: 88 | F15: 71 | G15: 81 | H15: 98 | I15: 87 | J15: =SUM(C15:I15) -> 615 | K15: ="第"&RANK(J15,J3:J46)&"名" -> 第25名
A16: C121414 | B16: =VLOOKUP(A16,学生信息表!$A$1:$B$56,2,FALSE) -> 颜怡璇 | C16: 87 | D16: 112 | E16: 92 | F16: 87 | G16: 68 | H16: 88 | I16: 85 | J16: =SUM(C16:I16) -> 619 | K16: ="第"&RANK(J16,J3:J46)&"名" -> 第23名
A17: C121415 | B17: =VLOOKUP(A17,学生信息表!$A$1:$B$56,2,FALSE) -> 章庭尹 | C17: 88 | D17: 94 | E17: 100 | F17: 81 | G17: 73 | H17: 76 | I17: 72 | J17: =SUM(C17:I17) -> 584 | K17: ="第"&RANK(J17,J3:J46)&"名" -> 第37名
A18: C121416 | B18: =VLOOKUP(A18,学生信息表!$A$1:$B$56,2,FALSE) -> 陈育彦 | C18: 118 | D18: 90 | E18: 92 | F18: 83 | G18: 51 | H18: 98 | I18: 87 | J18: =SUM(C18:I18) -> 619 | K18: ="第"&RANK(J18,J3:J46)&"名" -> 第23名
A19: C121417 | B19: =VLOOKUP(A19,学生信息表!$A$1:$B$56,2,FALSE) -> 周肇霖 | C19: 81 | D19: 82 | E19: 78 | F19: 71 | G19: 64 | H19: 95 | I19: 78 | J19: =SUM(C19:I19) -> 549 | K19: ="第"&RANK(J19,J3:J46)&"名" -> 第42名
A20: C121418 | B20: =VLOOKUP(A20,学生信息表!$A$1:$B$56,2,FALSE) -> 陈玟湖 | C20: 90 | D20: 90 | E20: 88 | F20: 86 | G20: 59 | H20: 99 | I20: 66 | J20: =SUM(C20:I20) -> 578 | K20: ="第"&RANK(J20,J3:J46)&"名" -> 第41名
A21: C121419 | B21: =VLOOKUP(A21,学生信息表!$A$1:$B$56,2,FALSE) -> 林海萱 | C21: 101 | D21: 104 | E21: 92 | F21: 93 | G21: 70 | H21: 88 | I21: 90 | J21: =SUM(C21:I21) -> 638 | K21: ="第"&RANK(J21,J3:J46)&"名" -> 第12名
A22: C121420 | B22: =VLOOKUP(A22,学生信息表!$A$1:$B$56,2,FALSE) -> 李嘉勇 | C22: 86 | D22: 75 | E22: 95 | F22: 94 | G22: 56 | H22: 96 | I22: 81 | J22: =SUM(C22:I22) -> 583 | K22: ="第"&RANK(J22,J3:J46)&"名" -> 第38名
A23: C121421 | B23: =VLOOKUP(A23,学生信息表!$A$1:$B$56,2,FALSE) -> 龚佩玲 | C23: 79 | D23: 106 | E23: 100 | F23: 78 | G23: 91 | H23: 87 | I23: 66 | J23: =SUM(C23:I23) -> 607 | K23: ="第"&RANK(J23,J3:J46)&"名" -> 第26名
A24: C121422 | B24: =VLOOKUP(A24,学生信息表!$A$1:$B$56,2,FALSE) -> 吴美州 | C24: 101 | D24: 92 | E24: 82 | F24: 95 | G24: 81 | H24: 99 | I24: 92 | J24: =SUM(C24:I24) -> 642 | K24: ="第"&RANK(J24,J3:J46)&"名" -> 第9名
A25: C121423 | B25: =VLOOKUP(A25,学生信息表!$A$1:$B$56,2,FALSE) -> 陈佩芬 | C25: 91 | D25: 89 | E25: 91 | F25: 88 | G25: 94 | H25: 82 | I25: 54 | J25: =SUM(C25:I25) -> 589 | K25: ="第"&RANK(J25,J3:J46)&"名" -> 第34名
A26: C121424 | B26: =VLOOKUP(A26,学生信息表!$A$1:$B$56,2,FALSE) -> 李咏妤 | C26: 95 | D26: 105 | E26: 94 | F26: 82 | G26: 85 | H26: 81 | I26: 87 | J26: =SUM(C26:I26) -> 629 | K26: ="第"&RANK(J26,J3:J46)&"名" -> 第21名
A27: C121425 | B27: =VLOOKUP(A27,学生信息表!$A$1:$B$56,2,FALSE) -> 张兆洋 | C27: 80 | D27: 95 | E27: 83 | F27: 91 | G27: 98 | H27: 78 | I27: 64 | J27: =SUM(C27:I27) -> 589 | K27: ="第"&RANK(J27,J3:J46)&"名" -> 第34名
A28: C121426 | B28: =VLOOKUP(A28,学生信息表!$A$1:$B$56,2,FALSE) -> 陈彦亨 | C28: 102 | D28: 112 | E28: 87 | F28: 91 | G28: 90 | H28: 91 | I28: 95 | J28: =SUM(C28:I28) -> 668 | K28: ="第"&RANK(J28,J3:J46)&"名" -> 第2名
A29: C121427 | B29: =VLOOKUP(A29,学生信息表!$A$1:$B$56,2,FALSE) -> 王美柏 | C29: 96 | D29: 96 | E29: 83 | F29: 98 | G29: 82 | H29: 88 | I29: 88 | J29: =SUM(C29:I29) -> 631 | K29: ="第"&RANK(J29,J3:J46)&"名" -> 第18名
A30: C121428 | B30: =VLOOKUP(A30,学生信息表!$A$1:$B$56,2,FALSE) -> 史姿蓉 | C30: 100 | D30: 118 | E30: 95 | F30: 90 | G30: 54 | H30: 96 | I30: 88 | J30: =SUM(C30:I30) -> 641 | K30: ="第"&RANK(J30,J3:J46)&"名" -> 第10名
A31: C121429 | B31: =VLOOKUP(A31,学生信息表!$A$1:$B$56,2,FALSE) -> 倪郁英 | C31: 96 | D31: 91 | E31: 94 | F31: 86 | G31: 67 | H31: 89 | I31: 78 | J31: =SUM(C31:I31) -> 601 | K31: ="第"&RANK(J31,J3:J46)&"名" -> 第31名
A32: C121430 | B32: =VLOOKUP(A32,学生信息表!$A$1:$B$56,2,FALSE) -> 黄启善 | C32: 89 | D32: 118 | E32: 95 | F32: 91 | G32: 99 | H32: 91 | I32: 65 | J32: =SUM(C32:I32) -> 648 | K32: ="第"&RANK(J32,J3:J46)&"名" -> 第7名
A33: C121431 | B33: =VLOOKUP(A33,学生信息表!$A$1:$B$56,2,FALSE) -> 李美紫 | C33: 102 | D33: 92 | E33: 93 | F33: 78 | G33: 54 | H33: 75 | I33: 88 | J33: =SUM(C33:I33) -> 582 | K33: ="第"&RANK(J33,J3:J46)&"名" -> 第40名
A34: C121432 | B34: =VLOOKUP(A34,学生信息表!$A$1:$B$56,2,FALSE) -> 蔡志瑞 | C34: 83 | D34: 97 | E34: 92 | F34: 87 | G34: 92 | H34: 95 | I34: 84 | J34: =SUM(C34:I34) -> 630 | K34: ="第"&RANK(J34,J3:J46)&"名" -> 第19名
A35: C121433 | B35: =VLOOKUP(A35,学生信息表!$A$1:$B$56,2,FALSE) -> 曹淑媛 | C35: 79 | D35: 104 | E35: 81 | F35: 97 | G35: 56 | H35: 91 | I35: 81 | J35: =SUM(C35:I35) -> 589 | K35: ="第"&RANK(J35,J3:J46)&"名" -> 第34名
A36: C121434 | B36: =VLOOKUP(A36,学生信息表!$A$1:$B$56,2,FALSE) -> 林慧韦 | C36: 95 | D36: 99 | E36: 99 | F36: 79 | G36: 92 | H36: 77 | I36: 93 | J36: =SUM(C36:I36) -> 634 | K36: ="第"&RANK(J36,J3:J46)&"名" -> 第15名
A37: C121435 | B37: =VLOOKUP(A37,学生信息表!$A$1:$B$56,2,FALSE) -> 许育萱 | C37: 99 | D37: 98 | E37: 90 | F37: 86 | G37: 65 | H37: 92 | I37: 96 | J37: =SUM(C37:I37) -> 626 | K37: ="第"&RANK(J37,J3:J46)&"名" -> 第22名
A38: C121436 | B38: =VLOOKUP(A38,学生信息表!$A$1:$B$56,2,FALSE) -> 廖皇荣 | C38: 101 | D38: 71 | E38: 96 | F38: 93 | G38: 52 | H38: 97 | I38: 86 | J38: =SUM(C38:I38) -> 596 | K38: ="第"&RANK(J38,J3:J46)&"名" -> 第32名
A39: C121437 | B39: =VLOOKUP(A39,学生信息表!$A$1:$B$56,2,FALSE) -> 周禹诚 | C39: 86 | D39: 107 | E39: 86 | F39: 97 | G39: 90 | H39: 92 | I39: 98 | J39: =SUM(C39:I39) -> 656 | K39: ="第"&RANK(J39,J3:J46)&"名" -> 第4名
A40: C121438 | B40: =VLOOKUP(A40,学生信息表!$A$1:$B$56,2,FALSE) -> 陈法璇 | C40: 90 | D40: 94 | E40: 80 | F40: 100 | G40: 58 | H40: 89 | I40: 96 | J40: =SUM(C40:I40) -> 607 | K40: ="第"&RANK(J40,J3:J46)&"名" -> 第26名
...

Sheet 学生信息表
A1: 学号 | B1: 姓名 | C1: 身份证号码 | D1: 性别 | E1: 籍贯
A2: C121417 | B2: 周肇霖 | C2: 420101200401051055 | D2: =IF(MOD(MID(C2,17,1)/2,1),"男","女") -> 男 | E2: 湖北
A3: C121301 | B3: 姜秀芬 | C3: 110102200512191513 | D3: =IF(MOD(MID(C3,17,1)/2,1),"男","女") -> 男 | E3: 北京
A4: C121201 | B4: 王初瑄 | C4: 110102200503292713 | D4: =IF(MOD(MID(C4,17,1)/2,1),"男","女") -> 男 | E4: 北京
A5: C121424 | B5: 李咏妤 | C5: 110102200404271532 | D5: =IF(MOD(MID(C5,17,1)/2,1),"男","女") -> 男 | E5: 北京
A6: C121404 | B6: 李政彬 | C6: 140302200505240451 | D6: =IF(MOD(MID(C6,17,1)/2,1),"男","女") -> 男 | E6: 山西
A7: C121001 | B7: 高名民 | C7: 110102200405281913 | D7: =IF(MOD(MID(C7,17,1)/2,1),"男","女") -> 男 | E7: 北京
A8: C121422 | B8: 吴美州 | C8: 110103200503040920 | D8: =IF(MOD(MID(C8,17,1)/2,1),"男","女") -> 女 | E8: 北京
A9: C121425 | B9: 张兆洋 | C9: 110103200503270623 | D9: =IF(MOD(MID(C9,17,1)/2,1),"男","女") -> 女 | E9: 北京
A10: C121401 | B10: 陈金志 | C10: 110103200504290936 | D10: =IF(MOD(MID(C10,17,1)/2,1),"男","女") -> 男 | E10: 北京
A11: C121439 | B11: 李依勇 | C11: 430103200508171548 | D11: =IF(MOD(MID(C11,17,1)/2,1),"男","女") -> 女 | E11: 湖南
A12: C120802 | B12: 黄绿泰 | C12: 140104200510261737 | D12: =IF(MOD(MID(C12,17,1)/2,1),"男","女") -> 男 | E12: 山西
A13: C121411 | B13: 杜思颖 | C13: 110104200403051216 | D13: =IF(MOD(MID(C13,17,1)/2,1),"男","女") -> 男 | E13: 北京
... A56: C121436 | B56: 廖皇荣 | C56: 11040520040531542X | D56: =IF(MOD(MID(C56,17,1)/2,1),"男","女") -> 女 | E56: 北京

Sheet 筛选
A1: 数学
A2: >=100
A3: 学号 | B3: 姓名 | C3: 语文 | D3: 数学 | E3: 英语 | F3: 物理 | G3: 化学 | H3: 品德 | I3: 历史
A4: C121401 | B4: =VLOOKUP(A4,学生信息表!$A$1:$B$56,2,FALSE) -> 陈金志 | C4: 97 | D4: 85 | E4: 82 | F4: 89 | G4: 69 | H4: 97 | I4: 83
A5: C121402 | B5: =VLOOKUP(A5,学生信息表!$A$1:$B$56,2,FALSE) -> 蔡君宏 | C5: 99 | D5: 116 | E5: 89 | F5: 100 | G5: 83 | H5: 95 | I5: 100
A6: C121403 | B6: =VLOOKUP(A6,学生信息表!$A$1:$B$56,2,FALSE) -> 吴佳宏 | C6: 98 | D6: 113 | E6: 92 | F6: 98 | G6: 69 | H6: 92 | I6: 84
A7: C121404 | B7: =VLOOKUP(A7,学生信息表!$A$1:$B$56,2,FALSE) -> 李政彬 | C7: 87 | D7: 99 | E7: 97 | F7: 93 | G7: 68 | H7: 87 | I7: 74
A8: C121405 | B8: =VLOOKUP(A8,学生信息表!$A$1:$B$56,2,FALSE) -> 黄惠茹 | C8: 103 | D8: 100 | E8: 85 | F8: 95 | G8: 82 | H8: 77 | I8: 92
A9: C121406 | B9: =VLOOKUP(A9,学生信息表!$A$1:$B$56,2,FALSE) -> 林雅婷 | C9: 96 | D9: 113 | E9: 96 | F9: 80 | G9: 91 | H9: 91 | I9: 95
A10: C121407 | B10: =VLOOKUP(A10,学生信息表!$A$1:$B$56,2,FALSE) -> 邓嘉玲 | C10: 109 | D10: 79 | E10: 93 | F10: 97 | G10: 97 | H10: 88 | I10: 89
A11: C121408 | B11: =VLOOKUP(A11,学生信息表!$A$1:$B$56,2,FALSE) -> 林丽芬 | C11: 81 | D11: 96 | E11: 96 | F11: 74 | G11: 80 | H11: 75 | I11: 94
A12: C121409 | B12: =VLOOKUP(A12,学生信息表!$A$1:$B$56,2,FALSE) -> 林敏茂 | C12: 103 | D12: 75 | E12: 92 | F12: 92 | G12: 74 | H12: 80 | I12: 67
A13: C121410 | B13: =VLOOKUP(A13,学生信息表!$A$1:$B$56,2,FALSE) -> 黄美善 | C13: 95 | D13: 83 | E13: 78 | F13: 80 | G13: 73 | H13: 71 | I13: 64
A14: C121411 | B14: =VLOOKUP(A14,学生信息表!$A$1:$B$56,2,FALSE) -> 杜思颖 | C14: 90 | D14: 107 | E14: 91 | F14: 90 | G14: 72 | H14: 88 | I14: 96
A15: C121412 | B15: =VLOOKUP(A15,学生信息表!$A$1:$B$56,2,FALSE) -> 陈俊嘉 | C15: 83 | D15: 74 | E15: 96 | F15: 74 | G15: 68 | H15: 77 | I15: 77
... A47: C121444 | B47: =VLOOKUP(A47,学生信息表!$A$1:$B$56,2,FALSE) -> 刘佳齐 | C47: 80 | D47: 118 | E47: 96 | F47: 84 | G47: 99 | H47: 93 | I47: 60
A48: 平均分 | C48: =AVERAGE(C4:C47) -> 93.568182 | D48: =AVERAGE(D4:D47) -> 97.022727 | E48: =AVERAGE(E4:E47) -> 90.977273 | F48: =AVERAGE(F4:F47) -> 88.068182 | G48: =AVERAGE(G4:G47) -> 75.477273 | H48: =AVERAGE(H4:H47) -> 88.113636 | I48: =AVERAGE(I4:I47) -> 83.590909
